<?xml version="1.0" ?>
<robot name="robot">
  <material name="black">
    <color rgba="0.0 0.0 0.0 1.0"/>
  </material>
  <material name="blue">
    <color rgba="0.0 0.0 0.8 1.0"/>
  </material>
  <material name="green">
    <color rgba="0.0 0.8 0.0 1.0"/>
  </material>
  <material name="grey">
    <color rgba="0.2 0.2 0.2 1.0"/>
  </material>
  <material name="silver">
    <color rgba="0.9137254901960784 0.9137254901960784 0.8470588235294118 1.0"/>
  </material>
  <material name="orange">
    <color rgba="1.0 0.4235294117647059 0.0392156862745098 1.0"/>
  </material>
  <material name="brown">
    <color rgba="0.8705882352941177 0.8117647058823529 0.7647058823529411 1.0"/>
  </material>
  <material name="red">
    <color rgba="0.8 0.0 0.0 1.0"/>
  </material>
  <material name="white">
    <color rgba="1.0 1.0 1.0 1.0"/>
  </material>
  <link name="base">
    <visual>
      <origin rpy="0 0 0" xyz="0 0 0"/>
      <geometry>
        <mesh filename="package://panda7_description/meshes/trunk.dae" scale="1 1 1"/>
      </geometry>
    </visual>
    <collision>
      <origin rpy="0 0 0" xyz="0 0 -0.0125"/>
      <geometry>
        <box size="0.49 0.32 0.235"/>
      </geometry>
    </collision>
    <!--<collision>
      <origin rpy="0 0 0" xyz="0.425 0 0.005"/>
      <geometry>
        <box size="0.05 0.27 0.200"/>
      </geometry> 
    </collision> 
    <collision>
      <origin rpy="0 0 0" xyz="-0.425 0 0.005"/>
      <geometry>
        <box size="0.05 0.27 0.200"/>
      </geometry>
    </collision> -->
    <inertial>
      <origin rpy="0 0 0" xyz="0.0014923112 -0.0014397771 -0.0094584260"/>
      <mass value="41.377848"/>
      <inertia ixx="0.47630359" ixy="-3.9611174E-03" ixz="0.020116265" iyy="1.8915135" iyz="-4.4176612E-03" izz="2.1035448"/>
    </inertial>
  </link>
    <link
    name="head_link">
    <inertial>
      <origin
        xyz="0.0 0.0 0.0"
        rpy="0 0 0" />
      <mass value="0.12"/>
      <inertia ixx="9.72e-05" ixy="0.0" ixz="0.0" iyy="9.72e-05" iyz="0.0" izz="9.72e-05"/>
    </inertial>
    <collision>
      <origin rpy="0 0 0" xyz="0.0 0.0 0.0"/>
      <geometry>
        <box size="0.05 0.27 0.180"/>
      </geometry>
    </collision>
  </link>
  <joint
    name="head_joint"
    type="fixed">
    <origin
      xyz="0.425 0 0.005"
      rpy="0 0 0" />
    <parent
      link="base" />
    <child
      link="head_link" />
    <axis
      xyz="0 0 0" />
  </joint>
    <link
    name="tail_link">
    <inertial>
      <origin
        xyz="0.0 0.0 0.0"
        rpy="0 0 0" />
      <mass value="0.12"/>
      <inertia ixx="9.72e-05" ixy="0.0" ixz="0.0" iyy="9.72e-05" iyz="0.0" izz="9.72e-05"/>
    </inertial>
    <collision>
      <origin rpy="0 0 0" xyz="0.0 0.0 0.0"/>
      <geometry>
        <box size="0.05 0.27 0.180"/>
      </geometry>
    </collision>
  </link>
  <joint
    name="tail_joint"
    type="fixed">
    <origin
      xyz="-0.425 0 0.005"
      rpy="0 0 0" />
    <parent
      link="base" />
    <child
      link="tail_link" />
    <axis
      xyz="0 0 0" />
  </joint>
    <link
    name="head_up_realsense_link">
    <inertial>
      <origin
        xyz="0.0 0.0 0.0"
        rpy="0 0 0" />
      <mass
        value="4.19E-15" />
      <inertia
        ixx="1.68E-27"
        ixy="0.0"
        ixz="0.0"
        iyy="1.68E-27"
        iyz="0.0"
        izz="1.68E-27" />
    </inertial>
    <visual>
      <origin rpy="0 0 0" xyz="0 0 0"/>
      <geometry>
        <mesh filename="package://panda7_description/meshes/d435i.dae" scale="1 1 1"/>
      </geometry>
      <material name="grey"/>
    </visual>
  </link>
  <joint
    name="head_up_realsense_joint"
    type="fixed">
    <origin
      xyz="0.4462 0 0.071"
      rpy="-1.57 0 -1.57" />
    <parent
      link="base" />
    <child
      link="head_up_realsense_link" />
    <axis
      xyz="0 0 0" />
  </joint>
  <link
    name="head_up_realsense_link_2">
    <inertial>
      <origin
        xyz="0.0 0.0 0.0"
        rpy="0 0 0" />
      <mass
        value="4.19E-15" />
      <inertia
        ixx="1.68E-27"
        ixy="0.0"
        ixz="0.0"
        iyy="1.68E-27"
        iyz="0.0"
        izz="1.68E-27" />
    </inertial>
    <visual>
      <origin rpy="0 0 0" xyz="0 0 0"/>
      <geometry>
        <mesh filename="package://panda7_description/meshes/d435i.dae" scale="1 1 1"/>
      </geometry>
      <material name="grey"/>
    </visual>
  </link>
  <joint
    name="head_up_realsense_joint_2"
    type="fixed">
    <origin
      xyz="0.4462 0 0.071"
      rpy="-1.57 0 -1.57" />
    <parent
      link="base" />
    <child
      link="head_up_realsense_link_2" />
    <axis
      xyz="0 0 0" />
  </joint>
  <link
    name="head_down_realsense_link">
    <inertial>
      <origin
        xyz="0.0 0.0 0.0"
        rpy="0 0 0" />
      <mass
        value="4.19E-15" />
      <inertia
        ixx="1.68E-27"
        ixy="0.0"
        ixz="0.0"
        iyy="1.68E-27"
        iyz="0.0"
        izz="1.68E-27" />
    </inertial>
    <visual>
      <origin rpy="0 0 0" xyz="0 0 0"/>
      <geometry>
        <mesh filename="package://panda7_description/meshes/d435i.dae" scale="1 1 1"/>
      </geometry>
      <material name="grey"/>
    </visual>
  </link>
  <joint
    name="head_down_realsense_joint"
    type="fixed">
    <origin
      xyz="0.44048 0 -0.057"
      rpy="-2.0761 0 -1.57" />
    <parent
      link="base" />
    <child
      link="head_down_realsense_link" />
    <axis
      xyz="0 0 0" />
  </joint>
  <joint name="FR_hip_joint" type="revolute">
    <origin rpy="0 0 0" xyz="0.325 -0.1125 0"/>
    <parent link="base"/>
    <child link="FR_hip"/>
    <axis xyz="1 0 0"/>
    <dynamics damping="0" friction="0" armature="0.035521"/>
    <limit effort="160" lower="-0.87" upper="0.69" velocity="19.3"/>
  </joint>
  <link name="FR_hip">
    <visual>
      <origin rpy="3.141592653589793 0 0" xyz="0 0 0"/>
      <geometry>
        <mesh filename="package://panda7_description/meshes/hip.dae" scale="1 1 1"/>
      </geometry>
      <material name="orange"/>
    </visual>
    <!--<collision>
      <origin rpy="1.57 0 0" xyz="0 0.035 0"/>
      <geometry>
        <cylinder radius="0.065" length="0.08"/>
      </geometry>
    </collision>-->
    <inertial>
      <origin rpy="0 0 0" xyz="-0.0011794 0.02693 -5.8859E-07"/>
      <mass value="2.7264"/>
      <inertia ixx="0.0043529" ixy="7.7592E-06" ixz="-9.9737E-09" iyy="0.0056391" iyz="1.7393E-08" izz="0.0047569"/>
    </inertial>
  </link>
  <joint name="FR_thigh_joint" type="revolute">
    <origin rpy="0 0 0" xyz="0 -0.126375 0"/>
    <parent link="FR_hip"/>
    <child link="FR_thigh"/>
    <axis xyz="0 1 0"/>
    <dynamics damping="0" friction="0" armature="0.022005"/>
    <limit effort="180" lower="-1.78" upper="3.40" velocity="21.6"/>
  </joint>
  <link name="FR_thigh">
    <visual>
      <origin rpy="0 0 0" xyz="0 0 0"/>
      <geometry>
        <mesh filename="package://panda7_description/meshes/thigh_mirror.dae" scale="1 1 1"/>
      </geometry>
      <material name="orange"/>
    </visual>
    <collision>
      <origin rpy="1.57 0 0" xyz="0 0.046 0"/>
      <geometry>
        <cylinder radius="0.067" length="0.129"/>
      </geometry>
    </collision>
    <collision>
      <origin rpy="0 0 0" xyz="-0.026 0 -0.18"/>
      <geometry>
        <box size="0.060 0.04 0.21"/>
      </geometry>
    </collision>
    <inertial>
      <origin rpy="0 0 0" xyz="0.008023 0.0407086 -0.0477057"/>
      <mass value="4.5843711"/>
      <inertia ixx="0.0568903" ixy="-1.3859024E-03" ixz="-0.0040888" iyy="0.055707534" iyz="-0.0090795" izz="0.0119193"/>
    </inertial>
  </link>
  <joint name="FR_calf_joint" type="revolute">
    <origin rpy="0 0 0" xyz="0 0 -0.34"/>
    <parent link="FR_thigh"/>
    <child link="FR_calf"/>
    <axis xyz="0 1 0"/>
    <dynamics damping="0" friction="0" armature="0.1289359"/>
    <limit effort="452" lower="-2.53" upper="-0.45" velocity="18.8"/>
  </joint>
  <link name="FR_calf">
    <visual>
      <origin rpy="0 0 0" xyz="0 0 0"/>
      <geometry>
        <mesh filename="package://panda7_description/meshes/calf.dae" scale="1 1 1"/>
      </geometry>
      <material name="orange"/>
    </visual>
    <collision>
      <origin rpy="0 1.5707963267948966 0" xyz="0.0 0 -0.17"/>
      <geometry>
        <box size="0.25 0.04 0.0495"/>
      </geometry>
    </collision>
    <collision>
      <origin rpy="1.57 0 0" xyz="-0.004 0 0"/>
      <geometry>
        <cylinder radius="0.023" length="0.054"/>
      </geometry>
    </collision>
    <collision>
      <origin rpy="1.57 0 0" xyz="-0.001 0 0.04"/>
      <geometry>
        <cylinder radius="0.0146" length="0.03"/>
      </geometry>
    </collision>
    <inertial>
      <origin rpy="0 0 0" xyz="-4.1136934E-03 -2.2641006E-06 -0.18227639"/>
      <mass value="0.82150729"/>
      <inertia ixx="0.017546212" ixy="-2.5076089E-09" ixz="-3.8977294E-05" iyy="0.017775449" iyz="-3.0610477E-07" izz="4.2961251E-04"/>
    </inertial>
  </link>
  <joint name="FR_foot_fixed" type="fixed" dont_collapse="true">
    <origin rpy="0 0 0" xyz="0 0 -0.34"/>
    <parent link="FR_calf"/>
    <child link="FR_FOOT"/>
  </joint>
  <link name="FR_FOOT">
    <collision>
      <origin rpy="0 0 0" xyz="0 0 0"/>
      <geometry>
        <sphere radius="0.045"/>
      </geometry>
    </collision>
    <inertial>
      <mass value="0.12"/>
      <inertia ixx="9.72e-05" ixy="0.0" ixz="0.0" iyy="9.72e-05" iyz="0.0" izz="9.72e-05"/>
    </inertial>
  </link>
  <joint name="FL_hip_joint" type="revolute">
    <origin rpy="0 0 0" xyz="0.325 0.1125 0"/>
    <parent link="base"/>
    <child link="FL_hip"/>
    <axis xyz="1 0 0"/>
    <dynamics damping="0" friction="0" armature="0.035521"/>
    <limit effort="160" lower="-0.69" upper="0.87" velocity="19.3"/>
  </joint>
  <link name="FL_hip">
    <visual>
      <origin rpy="0 0 0" xyz="0 0 0"/>
      <geometry>
        <mesh filename="package://panda7_description/meshes/hip.dae" scale="1 1 1"/>
      </geometry>
      <material name="orange"/>
    </visual>
    <!--<collision>
      <origin rpy="1.57 0 0" xyz="0 -0.035 0"/>
      <geometry>
        <cylinder radius="0.065" length="0.08"/>
      </geometry>
    </collision>-->
    <inertial>
      <origin rpy="0 0 0" xyz="-0.0011794 -0.02693 5.8859E-07"/>
      <mass value="2.7264"/>
      <inertia ixx="0.0043529" ixy="-7.7592E-06" ixz="9.9737E-09" iyy="0.0056391" iyz="1.7393E-08" izz="0.0047569"/>
    </inertial>
  </link>
  <joint name="FL_thigh_joint" type="revolute">
    <origin rpy="0 0 0" xyz="0 0.126375 0"/>
    <parent link="FL_hip"/>
    <child link="FL_thigh"/>
    <axis xyz="0 1 0"/>
    <dynamics damping="0" friction="0" armature="0.022005" />
    <limit effort="180" lower="-1.78" upper="3.40" velocity="21.6"/>
  </joint>
  <link name="FL_thigh">
    <visual>
      <origin rpy="0 0 0" xyz="0 0 0"/>
      <geometry>
        <mesh filename="package://panda7_description/meshes/thigh.dae" scale="1 1 1"/>
      </geometry>
      <material name="orange"/>
    </visual>
    <collision>
      <origin rpy="1.57 0 0" xyz="0 -0.046 0"/>
      <geometry>
        <cylinder radius="0.067" length="0.129"/>
      </geometry>
    </collision>
    <collision>
      <origin rpy="0 0 0" xyz="-0.026 0 -0.18"/>
      <geometry>
        <box size="0.060 0.04 0.21"/>
      </geometry>
    </collision>
    <inertial>
      <origin rpy="0 0 0" xyz="0.008023 -0.0407086 -0.0477057"/>
      <mass value="4.5843711"/>
      <inertia ixx="0.0568903" ixy="1.3859024E-03" ixz="-0.0040888" iyy="0.055707534" iyz="0.0090795" izz="0.0119193"/>
    </inertial>
  </link>
  <joint name="FL_calf_joint" type="revolute">
    <origin rpy="0 0 0" xyz="0 0 -0.34"/>
    <parent link="FL_thigh"/>
    <child link="FL_calf"/>
    <axis xyz="0 1 0"/>
    <dynamics damping="0" friction="0" armature="0.1289359"/>
    <limit effort="452" lower="-2.53" upper="-0.45" velocity="18.8"/>
  </joint>
  <link name="FL_calf">
    <visual>
      <origin rpy="0 0 0" xyz="0 0 0"/>
      <geometry>
        <mesh filename="package://panda7_description/meshes/calf.dae" scale="1 1 1"/>
      </geometry>
      <material name="orange"/>
    </visual>
    <collision>
      <origin rpy="0 1.5707963267948966 0" xyz="0.0 0 -0.17"/>
      <geometry>
        <box size="0.25 0.04 0.0495"/>
      </geometry>
    </collision>
    <collision>
      <origin rpy="1.57 0 0" xyz="-0.004 0 0"/>
      <geometry>
        <cylinder radius="0.023" length="0.054"/>
      </geometry>
    </collision>
    <collision>
      <origin rpy="1.57 0 0" xyz="-0.001 0 0.04"/>
      <geometry>
        <cylinder radius="0.0146" length="0.03"/>
      </geometry>
    </collision>
    <inertial>
      <origin rpy="0 0 0" xyz="-4.1136934E-03 2.2641006E-06 -0.18227639"/>
      <mass value="0.82150729"/>
      <inertia ixx="0.017546212" ixy="-2.5076089E-09" ixz="3.8977294E-05" iyy="0.017775449" iyz="3.0610477E-07" izz="4.2961251E-04"/>
    </inertial>
  </link>
  <joint name="FL_foot_fixed" type="fixed" dont_collapse="true">
    <origin rpy="0 0 0" xyz="0 0 -0.34"/>
    <parent link="FL_calf"/>
    <child link="FL_FOOT"/>
  </joint>
  <link name="FL_FOOT">
    <collision>
      <origin rpy="0 0 0" xyz="0 0 0"/>
      <geometry>
        <sphere radius="0.045"/>
      </geometry>
    </collision>
    <inertial>
      <mass value="0.12"/>
      <inertia ixx="9.72e-05" ixy="0.0" ixz="0.0" iyy="9.72e-05" iyz="0.0" izz="9.72e-05"/>
    </inertial>
  </link>
  <joint name="RR_hip_joint" type="revolute">
    <origin rpy="0 0 0" xyz="-0.325 -0.1125 0"/>
    <parent link="base"/>
    <child link="RR_hip"/>
    <axis xyz="1 0 0"/>
    <dynamics damping="0" friction="0" armature="0.035521"/>
    <limit effort="160" lower="-0.87" upper="0.69" velocity="19.3"/>
  </joint>
  <link name="RR_hip">
    <visual>
      <origin rpy="3.141592653589793 3.141592653589793 0" xyz="0 0 0"/>
      <geometry>
        <mesh filename="package://panda7_description/meshes/hip.dae" scale="1 1 1"/>
      </geometry>
      <material name="orange"/>
    </visual>
    <!--<collision>
      <origin rpy="1.57 0 0" xyz="0 0.035 0"/>
      <geometry>
        <cylinder radius="0.065" length="0.08"/>
      </geometry>
    </collision>-->
    <inertial>
      <origin rpy="0 0 0" xyz="0.0011794 0.02693 5.8859E-07"/>
      <mass value="2.7264"/>
      <inertia ixx="0.0043529" ixy="-7.7592E-06" ixz="-9.9737E-09" iyy="0.0056391" iyz="-1.7393E-08" izz="0.0047569"/>
    </inertial>
  </link>
  <joint name="RR_thigh_joint" type="revolute">
    <origin rpy="0 0 0" xyz="0 -0.126375 0"/>
    <parent link="RR_hip"/>
    <child link="RR_thigh"/>
    <axis xyz="0 1 0"/>
    <dynamics damping="0" friction="0" armature="0.022005"/>
    <limit effort="180" lower="-1.30" upper="4.00" velocity="21.6"/>
  </joint>
  <link name="RR_thigh">
    <visual>
      <origin rpy="0 0 0" xyz="0 0 0"/>
      <geometry>
        <mesh filename="package://panda7_description/meshes/thigh_mirror.dae" scale="1 1 1"/>
      </geometry>
      <material name="orange"/>
    </visual>
    <collision>
      <origin rpy="1.57 0 0" xyz="0 0.046 0"/>
      <geometry>
        <cylinder radius="0.067" length="0.129"/>
      </geometry>
    </collision>
    <collision>
      <origin rpy="0 0 0" xyz="-0.026 0 -0.18"/>
      <geometry>
        <box size="0.060 0.04 0.21"/>
      </geometry>
    </collision>
    <inertial>
      <origin rpy="0 0 0" xyz="0.008023 0.0407086 -0.0477057"/>
      <mass value="4.5843711"/>
      <inertia ixx="0.0568903" ixy="-1.3859024E-03" ixz="-0.0040888" iyy="0.055707534" iyz="-0.0090795" izz="0.0119193"/>
    </inertial>
  </link>
  <joint name="RR_calf_joint" type="revolute">
    <origin rpy="0 0 0" xyz="0 0 -0.34"/>
    <parent link="RR_thigh"/>
    <child link="RR_calf"/>
    <axis xyz="0 1 0"/>
    <dynamics damping="0" friction="0" armature="0.1289359"/>
    <limit effort="452" lower="-2.53" upper="-0.45" velocity="18.8"/>
  </joint>
  <link name="RR_calf">
    <visual>
      <origin rpy="0 0 0" xyz="0 0 0"/>
      <geometry>
        <mesh filename="package://panda7_description/meshes/calf.dae" scale="1 1 1"/>
      </geometry>
      <material name="orange"/>
    </visual>
    <collision>
      <origin rpy="0 1.5707963267948966 0" xyz="0.0 0 -0.17"/>
      <geometry>
        <box size="0.25 0.04 0.0495"/>
      </geometry>
    </collision>
    <collision>
      <origin rpy="1.57 0 0" xyz="-0.004 0 0"/>
      <geometry>
        <cylinder radius="0.023" length="0.054"/>
      </geometry>
    </collision>
    <collision>
      <origin rpy="1.57 0 0" xyz="-0.001 0 0.04"/>
      <geometry>
        <cylinder radius="0.0146" length="0.03"/>
      </geometry>
    </collision>
    <inertial>
      <origin rpy="0 0 0" xyz="-4.1136934E-03 -2.2641006E-06 -0.18227639"/>
      <mass value="0.82150729"/>
      <inertia ixx="0.017546212" ixy="-2.5076089E-09" ixz="-3.8977294E-05" iyy="0.017775449" iyz="-3.0610477E-07" izz="4.2961251E-04"/>
    </inertial>
  </link>
  <joint name="RR_foot_fixed" type="fixed" dont_collapse="true">
    <origin rpy="0 0 0" xyz="0 0 -0.34"/>
    <parent link="RR_calf"/>
    <child link="RR_FOOT"/>
  </joint>
<!-- imu -->
  <link name="imu_link">
    <inertial>
      <origin xyz="0 0 0" rpy="0 0 0" />
      <mass value="0" />
      <inertia ixx="0" ixy="0" ixz="0" iyy="0" iyz="0" izz="0" />
    </inertial>
  </link>
  <joint name="imu_joint" type="fixed">
    <origin xyz="-0.02557 0 0.04232" rpy="0 0 0" />
    <parent link="base" />
    <child link="imu_link" />
    <axis xyz="0 0 0" />
  </joint>
<!-- imu -->
  <link name="RR_FOOT">
    <collision>
      <origin rpy="0 0 0" xyz="0 0 0"/>
      <geometry>
        <sphere radius="0.045"/>
      </geometry>
    </collision>
    <inertial>
      <mass value="0.12"/>
      <inertia ixx="9.72e-05" ixy="0.0" ixz="0.0" iyy="9.72e-05" iyz="0.0" izz="9.72e-05"/>
    </inertial>
  </link>
  <joint name="RL_hip_joint" type="revolute">
    <origin rpy="0 0 0" xyz="-0.325 0.1125 0"/>
    <parent link="base"/>
    <child link="RL_hip"/>
    <axis xyz="1 0 0"/>
    <dynamics damping="0" friction="0" armature="0.035521"/>
    <limit effort="160" lower="-0.69" upper="0.87" velocity="19.3"/>
  </joint>
  <link name="RL_hip">
    <visual>
      <origin rpy="0 3.141592653589793 0" xyz="0 0 0"/>
      <geometry>
        <mesh filename="package://panda7_description/meshes/hip.dae" scale="1 1 1"/>
      </geometry>
      <material name="orange"/>
    </visual>
    <!--<collision>
      <origin rpy="1.57 0 0" xyz="0 -0.035 0"/>
      <geometry>
        <cylinder radius="0.065" length="0.08"/>
      </geometry>
    </collision>-->
    <inertial>
      <origin rpy="0 0 0" xyz="0.0011794 -0.02693 -5.8859E-07"/>
      <mass value="2.7264"/>
      <inertia ixx="0.0043529" ixy="7.7592E-06" ixz="9.9737E-09" iyy="0.0056391" iyz="-1.7393E-08" izz="0.0047569"/>
    </inertial>
  </link>
  <joint name="RL_thigh_joint" type="revolute">
    <origin rpy="0 0 0" xyz="0 0.126375 0"/>
    <parent link="RL_hip"/>
    <child link="RL_thigh"/>
    <axis xyz="0 1 0"/>
    <dynamics damping="0" friction="0" armature="0.022005"/>
    <limit effort="180" lower="-1.30" upper="4.00" velocity="21.6"/>
  </joint>
  <link name="RL_thigh">
    <visual>
      <origin rpy="0 0 0" xyz="0 0 0"/>
      <geometry>
        <mesh filename="package://panda7_description/meshes/thigh.dae" scale="1 1 1"/>
      </geometry>
      <material name="orange"/>
    </visual>
    <collision>
      <origin rpy="1.57 0 0" xyz="0 -0.046 0"/>
      <geometry>
        <cylinder radius="0.067" length="0.129"/>
      </geometry>
    </collision>
    <collision>
      <origin rpy="0 0 0" xyz="-0.026 0 -0.18"/>
      <geometry>
        <box size="0.060 0.04 0.21"/>
      </geometry>
    </collision>
    <inertial>
      <origin rpy="0 0 0" xyz="0.008023 -0.0407086 -0.0477057"/>
      <mass value="4.5843711"/>
      <inertia ixx="0.0568903" ixy="1.3859024E-03" ixz="-0.0040888" iyy="0.055707534" iyz="0.0090795" izz="0.0119193"/>
    </inertial>
  </link>
  <joint name="RL_calf_joint" type="revolute">
    <origin rpy="0 0 0" xyz="0 0 -0.34"/>
    <parent link="RL_thigh"/>
    <child link="RL_calf"/>
    <axis xyz="0 1 0"/>
    <dynamics damping="0" friction="0" armature="0.1289359"/>
    <limit effort="452" lower="-2.53" upper="-0.45" velocity="18.8"/>
  </joint>
  <link name="RL_calf">
    <visual>
      <origin rpy="0 0 0" xyz="0 0 0"/>
      <geometry>
        <mesh filename="package://panda7_description/meshes/calf.dae" scale="1 1 1"/>
      </geometry>
      <material name="orange"/>
    </visual>
    <collision>
      <origin rpy="0 1.5707963267948966 0" xyz="0.0 0 -0.17"/>
      <geometry>
        <box size="0.25 0.04 0.0495"/>
      </geometry>
    </collision>
    <collision>
      <origin rpy="1.57 0 0" xyz="-0.004 0 0"/>
      <geometry>
        <cylinder radius="0.023" length="0.054"/>
      </geometry>
    </collision>
    <collision>
      <origin rpy="1.57 0 0" xyz="-0.001 0 0.04"/>
      <geometry>
        <cylinder radius="0.0146" length="0.03"/>
      </geometry>
    </collision>
    <inertial>
      <origin rpy="0 0 0" xyz="-4.1136934E-03 2.2641006E-06 -0.18227639"/>
      <mass value="0.82150729"/>
      <inertia ixx="0.017546212" ixy="-2.5076089E-09" ixz="3.8977294E-05" iyy="0.017775449" iyz="3.0610477E-07" izz="4.2961251E-04"/>
    </inertial>
  </link>
  <joint name="RL_foot_fixed" type="fixed" dont_collapse="true">
    <origin rpy="0 0 0" xyz="0 0 -0.34"/>
    <parent link="RL_calf"/>
    <child link="RL_FOOT"/>
  </joint>
  <link name="RL_FOOT">
    <collision>
      <origin rpy="0 0 0" xyz="0 0 0"/>
      <geometry>
        <sphere radius="0.045"/>
      </geometry>
    </collision>
    <inertial>
      <mass value="0.12"/>
      <inertia ixx="9.72e-05" ixy="0.0" ixz="0.0" iyy="9.72e-05" iyz="0.0" izz="9.72e-05"/>
    </inertial>
  </link>


  <transmission name="FL_hip_tran">
    <type>transmission_interface/SimpleTransmission</type>
    <joint name="FL_hip_joint">
      <hardwareInterface>hardware_interface/EffortJointInterface</hardwareInterface>
    </joint>
    <actuator name="FL_hip_motor">
      <hardwareInterface>hardware_interface/EffortJointInterface</hardwareInterface>
      <mechanicalReduction>1</mechanicalReduction>
    </actuator>
  </transmission>
  <transmission name="FL_thigh_tran">
    <type>transmission_interface/SimpleTransmission</type>
    <joint name="FL_thigh_joint">
      <hardwareInterface>hardware_interface/EffortJointInterface</hardwareInterface>
    </joint>
    <actuator name="FL_thigh_motor">
      <hardwareInterface>hardware_interface/EffortJointInterface</hardwareInterface>
      <mechanicalReduction>1</mechanicalReduction>
    </actuator>
  </transmission>
  <transmission name="FL_calf_tran">
    <type>transmission_interface/SimpleTransmission</type>
    <joint name="FL_calf_joint">
      <hardwareInterface>hardware_interface/EffortJointInterface</hardwareInterface>
    </joint>
    <actuator name="FL_calf_motor">
      <hardwareInterface>hardware_interface/EffortJointInterface</hardwareInterface>
      <mechanicalReduction>1</mechanicalReduction>
    </actuator>
  </transmission>

  <transmission name="FR_hip_tran">
    <type>transmission_interface/SimpleTransmission</type>
    <joint name="FR_hip_joint">
      <hardwareInterface>hardware_interface/EffortJointInterface</hardwareInterface>
    </joint>
    <actuator name="FR_hip_motor">
      <hardwareInterface>hardware_interface/EffortJointInterface</hardwareInterface>
      <mechanicalReduction>1</mechanicalReduction>
    </actuator>
  </transmission>
  <transmission name="FR_thigh_tran">
    <type>transmission_interface/SimpleTransmission</type>
    <joint name="FR_thigh_joint">
      <hardwareInterface>hardware_interface/EffortJointInterface</hardwareInterface>
    </joint>
    <actuator name="FR_thigh_motor">
      <hardwareInterface>hardware_interface/EffortJointInterface</hardwareInterface>
      <mechanicalReduction>1</mechanicalReduction>
    </actuator>
  </transmission>
  <transmission name="FR_calf_tran">
    <type>transmission_interface/SimpleTransmission</type>
    <joint name="FR_calf_joint">
      <hardwareInterface>hardware_interface/EffortJointInterface</hardwareInterface>
    </joint>
    <actuator name="FR_calf_motor">
      <hardwareInterface>hardware_interface/EffortJointInterface</hardwareInterface>
      <mechanicalReduction>1</mechanicalReduction>
    </actuator>
  </transmission>

  <transmission name="RL_hip_tran">
    <type>transmission_interface/SimpleTransmission</type>
    <joint name="RL_hip_joint">
      <hardwareInterface>hardware_interface/EffortJointInterface</hardwareInterface>
    </joint>
    <actuator name="RL_hip_motor">
      <hardwareInterface>hardware_interface/EffortJointInterface</hardwareInterface>
      <mechanicalReduction>1</mechanicalReduction>
    </actuator>
  </transmission>
  <transmission name="RL_thigh_tran">
    <type>transmission_interface/SimpleTransmission</type>
    <joint name="RL_thigh_joint">
      <hardwareInterface>hardware_interface/EffortJointInterface</hardwareInterface>
    </joint>
    <actuator name="RL_thigh_motor">
      <hardwareInterface>hardware_interface/EffortJointInterface</hardwareInterface>
      <mechanicalReduction>1</mechanicalReduction>
    </actuator>
  </transmission>
  <transmission name="RL_calf_tran">
    <type>transmission_interface/SimpleTransmission</type>
    <joint name="RL_calf_joint">
      <hardwareInterface>hardware_interface/EffortJointInterface</hardwareInterface>
    </joint>
    <actuator name="RL_calf_motor">
      <hardwareInterface>hardware_interface/EffortJointInterface</hardwareInterface>
      <mechanicalReduction>1</mechanicalReduction>
    </actuator>
  </transmission>

  <transmission name="RR_hip_tran">
    <type>transmission_interface/SimpleTransmission</type>
    <joint name="RR_hip_joint">
      <hardwareInterface>hardware_interface/EffortJointInterface</hardwareInterface>
    </joint>
    <actuator name="RR_hip_motor">
      <hardwareInterface>hardware_interface/EffortJointInterface</hardwareInterface>
      <mechanicalReduction>1</mechanicalReduction>
    </actuator>
  </transmission>
  <transmission name="RR_thigh_tran">
    <type>transmission_interface/SimpleTransmission</type>
    <joint name="RR_thigh_joint">
      <hardwareInterface>hardware_interface/EffortJointInterface</hardwareInterface>
    </joint>
    <actuator name="RR_thigh_motor">
      <hardwareInterface>hardware_interface/EffortJointInterface</hardwareInterface>
      <mechanicalReduction>1</mechanicalReduction>
    </actuator>
  </transmission>
  <transmission name="RR_calf_tran">
    <type>transmission_interface/SimpleTransmission</type>
    <joint name="RR_calf_joint">
      <hardwareInterface>hardware_interface/EffortJointInterface</hardwareInterface>
    </joint>
    <actuator name="RR_calf_motor">
      <hardwareInterface>hardware_interface/EffortJointInterface</hardwareInterface>
      <mechanicalReduction>1</mechanicalReduction>
    </actuator>
  </transmission>



</robot>

